<?xml version="1.0"?>
<!--
Copyright (c) 2013, Goncalo Cabrita, ISR University of Coimbra
All rights reserved.

Redistribution and use in source and binary forms, with or without
modification, are permitted provided that the following conditions are met:
    * Redistributions of source code must retain the above copyright
      notice, this list of conditions and the following disclaimer.
    * Redistributions in binary form must reproduce the above copyright
      notice, this list of conditions and the following disclaimer in the
      documentation and/or other materials provided with the distribution.
    * Neither the name of Clearpath Robotics nor the
      names of its contributors may be used to endorse or promote products
      derived from this software without specific prior written permission.

THIS SOFTWARE IS PROVIDED BY THE COPYRIGHT HOLDERS AND CONTRIBUTORS "AS IS" AND
ANY EXPRESS OR IMPLIED WARRANTIES, INCLUDING, BUT NOT LIMITED TO, THE IMPLIED
WARRANTIES OF MERCHANTABILITY AND FITNESS FOR A PARTICULAR PURPOSE ARE
DISCLAIMED. IN NO EVENT SHALL THE COPYRIGHT HOLDERS BE LIABLE FOR ANY
DIRECT, INDIRECT, INCIDENTAL, SPECIAL, EXEMPLARY, OR CONSEQUENTIAL DAMAGES
(INCLUDING, BUT NOT LIMITED TO, PROCUREMENT OF SUBSTITUTE GOODS OR SERVICES;
LOSS OF USE, DATA, OR PROFITS; OR BUSINESS INTERRUPTION) HOWEVER CAUSED AND
ON ANY THEORY OF LIABILITY, WHETHER IN CONTRACT, STRICT LIABILITY, OR TORT
(INCLUDING NEGLIGENCE OR OTHERWISE) ARISING IN ANY WAY OUT OF THE USE OF THIS
SOFTWARE, EVEN IF ADVISED OF THE POSSIBILITY OF SUCH DAMAGE.
-->

<robot xmlns:sensor="http://playerstage.sourceforge.net/gazebo/xmlschema/#sensor"
	xmlns:controller="http://playerstage.sourceforge.net/gazebo/xmlschema/#controller"
	xmlns:interface="http://playerstage.sourceforge.net/gazebo/xmlschema/#interface"
	xmlns:xacro="http://ros.org/wiki/xacro" name="fsr_husky_arm">
<xacro:macro name="fsr_husky_arm" params="parent x y z rx ry rz"> 
  <link
    name="base_arm_link">
    <inertial>
      <origin
        xyz="0.0748500402726595 0.0136470618219005 -0.0925164110070736"
        rpy="0 0 0" />
      <mass
        value="0.215286927386896" />
      <inertia
        ixx="0.00151952875960782"
        ixy="-5.00239624175035E-05"
        ixz="-0.000104007201846032"
        iyy="0.00181155299285244"
        iyz="0.000216578123822788"
        izz="0.000582288664758318" />
    </inertial>
    <visual>
      <origin
        xyz="0 0 0"
        rpy="0 0 0" />
      <geometry>
        <mesh
          filename="package://fsr_husky_description/models/arm/base_arm_link.STL" />
      </geometry>
      <material
        name="Gray">
        <color
          rgba="0.776470588235294 0.756862745098039 0.737254901960784 1" />
      </material>
    </visual>
    <collision>
      <origin
        xyz="0 0 0"
        rpy="0 0 0" />
      <geometry>
        <mesh
          filename="package://fsr_husky_description/models/arm/base_arm_link.STL" />
      </geometry>
    </collision>
  </link>
  <gazebo reference="base_arm_link">
        <material>Gazebo/Grey</material>
        <turnGravityOff>true</turnGravityOff>
    </gazebo>

  <joint name="arm_joint" type="fixed">
			<parent link="${parent}"/>
			<child link="base_arm_link"/>
			<origin xyz="${x} ${y} ${z}" rpy="${rx} ${ry} ${rz}" /> 
  </joint>

  <link
    name="arm_axel">
    <inertial>
      <origin
        xyz="-6.71167554128979E-05 0.147555068632442 -5.01352348164508E-07"
        rpy="0 0 0" />
      <mass
        value="0.116752432749066" />
      <inertia
        ixx="0.000715149281043979"
        ixy="7.80945806556874E-07"
        ixz="6.95759354868419E-10"
        iyy="8.63256490972112E-06"
        iyz="-1.92225108206073E-09"
        izz="0.000715441962309322" />
    </inertial>
    <visual>
      <origin
        xyz="0 0 0"
        rpy="0 0 0" />
      <geometry>
        <mesh
          filename="package://fsr_husky_description/models/arm/arm_axel.STL" />
      </geometry>
      <material
        name="Gray">
        <color
          rgba="0.776470588235294 0.756862745098039 0.737254901960784 1" />
      </material>
    </visual>
    <collision>
      <origin
        xyz="0 0 0"
        rpy="0 0 0" />
      <geometry>
        <mesh
          filename="package://fsr_husky_description/models/arm/arm_axel.STL" />
      </geometry>
    </collision>
  </link>
  <gazebo reference="arm_axel">
        <material>Gazebo/Grey</material>
        <turnGravityOff>true</turnGravityOff>
    </gazebo>

  <joint
    name="arm_axel_joint"
    type="revolute">
    <origin
      xyz="0.06 0.152 0"
      rpy="1.5708 0 0" />
    <parent
      link="base_arm_link" />
    <child
      link="arm_axel" />
    <axis
      xyz="0 -1 0" />
    <limit
      lower="-1.5708"
      upper="1.5708"
      effort="100"
      velocity="0.5" />
  </joint>

  <link
    name="upper_arm">
    <inertial>
      <origin
        xyz="0.000102539584510564 0.025319004836415 0.373317706752181"
        rpy="0 0 0" />
      <mass
        value="0.310661228623748" />
      <inertia
        ixx="0.0301188716585458"
        ixy="-4.68610675580059E-08"
        ixz="1.48034298202518E-05"
        iyy="0.0301182394443099"
        iyz="-0.000152720615635198"
        izz="8.7451640283179E-05" />
    </inertial>
    <visual>
      <origin
        xyz="0 0 0"
        rpy="0 0 0" />
      <geometry>
        <mesh
          filename="package://fsr_husky_description/models/arm/upper_arm.STL" />
      </geometry>
      <material
        name="DarkGray">
        <color
          rgba="0.776470588235294 0.756862745098039 0.737254901960784 1" />
      </material>
    </visual>
    <collision>
      <origin
        xyz="0 0 0"
        rpy="0 0 0" />
      <geometry>
        <mesh
          filename="package://fsr_husky_description/models/arm/upper_arm.STL" />
      </geometry>
    </collision>
  </link>
  <gazebo reference="upper_arm">
        <material>Gazebo/Grey</material>
        <turnGravityOff>true</turnGravityOff>
    </gazebo>

  <joint
    name="upper_arm_joint"
    type="revolute">
    <origin
      xyz="0 0.1459 -0.0096445"
      rpy="-1.5708 0 -1.5708" />
    <parent
      link="arm_axel" />
    <child
      link="upper_arm" />
    <axis
      xyz="0 1 0" />
    <limit
      lower="-0.5"
      upper="0.25"
      effort="20"
      velocity="0.5" />
  </joint>

  <link
    name="metal_detector_arm">
    <inertial>
      <origin
        xyz="0.00200170148149059 -0.0639004587205252 -0.0667324909004516"
        rpy="0 0 0" />
      <mass
	value="0.00001" /><!--value="0.730115545526703" />-->
      <inertia
        ixx="0.00564260404067653"
        ixy="4.21272987506857E-05"
        ixz="4.78655101148471E-05"
        iyy="0.00114533989924875"
        iyz="0.00095063627641457"
        izz="0.00479397824386875" />
    </inertial>
    <visual>
      <origin
        xyz="0 0 0"
        rpy="0 0 0" />
      <geometry>
        <mesh
          filename="package://fsr_husky_description/models/arm/metal_detector_arm.STL" />
      </geometry>
      <material
        name="DarkGray">
        <color
          rgba="0.494117647058824 0.494117647058824 0.494117647058824 1" />
      </material>
    </visual>
    <collision>
      <origin
        xyz="0 0 0"
        rpy="0 0 0" />
      <geometry>
        <mesh
          filename="package://fsr_husky_description/models/arm/metal_detector_arm.STL" />
      </geometry>
    </collision>
  </link>
  <gazebo reference="metal_detector_arm">
        <material>Gazebo/Grey</material>
        <turnGravityOff>true</turnGravityOff>
    </gazebo>

  <joint
    name="metal_detector_arm_joint"
    type="revolute">
    <mimic
      joint="upper_arm_joint"
      multiplier="-1" />
    <origin
      xyz="0 0 0.8475"
      rpy="1.5708 -1.5708 0" />
    <parent
      link="upper_arm" />
    <child
      link="metal_detector_arm" />
    <axis
      xyz="0 0 -1" />
    <limit
      lower="-0.25"
      upper="0.5"
      effort="20"
      velocity="0.5" />
  </joint>

  <link
    name="metal_detector_antenna">
    <inertial>
      <origin
        xyz="3.6833E-07 0.011468 -0.12477"
        rpy="0 0 0" />
      <mass
	value="0.00001" /><!--value="12.099" />-->
      <inertia
        ixx="0.060468"
        ixy="-4.3221E-09"
        ixz="5.3405E-07"
        iyy="0.27654"
        iyz="-0.0010461"
        izz="0.21765" />
    </inertial>
    <visual>
      <origin
        xyz="0 0 0"
        rpy="0 0 0" />
      <geometry>
        <mesh
          filename="package://fsr_husky_description/models/arm/metal_detector_antenna.STL" />
      </geometry>
      <material
        name="ArmyGreen">
        <color
          rgba="0.3 0.332 0.128 1" />
      </material>
    </visual>
    <collision>
      <origin
        xyz="0 0 0"
        rpy="0 0 0" />
      <geometry>
        <mesh
          filename="package://fsr_husky_description/models/arm/metal_detector_antenna.STL" />
      </geometry>
    </collision>
  </link>
  <gazebo reference="metal_detector_antenna">
        <material>Gazebo/Green</material>
        <turnGravityOff>true</turnGravityOff>
    </gazebo>

  <joint
    name="metal_detector_antenna_joint"
    type="fixed">
    <origin
      xyz="0 -0.33276 0.095344"
      rpy="0 0 0" />
    <parent
      link="metal_detector_arm" />
    <child
      link="metal_detector_antenna" />
    <axis
      xyz="0 0 0" />
  </joint>

  <link
    name="lower_arm">
    <inertial>
      <origin
        xyz="-4.03262433168461E-08 0.0238835580685394 0.38020982511275"
        rpy="0 0 0" />
      <mass
        value="0.315289032495142" />
      <inertia
        ixx="0.0311225242878348"
        ixy="-2.44666563034439E-10"
        ixz="3.98116348654419E-09"
        iyy="0.0311222097229973"
        iyz="-0.000155853742938512"
        izz="8.78358578959995E-05" />
    </inertial>
    <visual>
      <origin
        xyz="0 0 0"
        rpy="0 0 0" />
      <geometry>
        <mesh
          filename="package://fsr_husky_description/models/arm/lower_arm.STL" />
      </geometry>
      <material
        name="DarkGray">
        <color
          rgba="0.776470588235294 0.756862745098039 0.737254901960784 1" />
      </material>
    </visual>
    <collision>
      <origin
        xyz="0 0 0"
        rpy="0 0 0" />
      <geometry>
        <mesh
          filename="package://fsr_husky_description/models/arm/lower_arm.STL" />
      </geometry>
    </collision>
  </link>
  <gazebo reference="lower_arm">
        <material>Gazebo/Grey</material>
        <turnGravityOff>true</turnGravityOff>
    </gazebo>

  <joint
    name="lower_arm_joint"
    type="revolute">
    <mimic
      joint="upper_arm_joint" />
    <origin
      xyz="0 0.0809 -0.011058"
      rpy="-1.5708 0 -1.5708" />
    <parent
      link="arm_axel" />
    <child
      link="lower_arm" />
    <axis
      xyz="0 1 0" />
    <limit
      lower="-0.5"
      upper="0.25"
      effort="20"
      velocity="0.5" />
  </joint>
  
  <transmission name="upper_lift">
    <type>transmission_interface/SimpleTransmission</type>
    <joint name="upper_arm_joint"/>
    <actuator name="upper_lift_motor">
      <hardwareInterface>EffortJointInterface</hardwareInterface>
      <mechanicalReduction>1</mechanicalReduction>
    </actuator>
  </transmission>
  
  <transmission name="lower_lift">
    <type>transmission_interface/SimpleTransmission</type>
    <joint name="lower_arm_joint"/>
    <actuator name="lower_lift_motor">
      <hardwareInterface>EffortJointInterface</hardwareInterface>
      <mechanicalReduction>1</mechanicalReduction>
    </actuator>
  </transmission>
  
  <transmission name="mirror_lift">
    <type>transmission_interface/SimpleTransmission</type>
    <joint name="metal_detector_arm_joint"/>
    <actuator name="mirror_lift_motor">
      <hardwareInterface>EffortJointInterface</hardwareInterface>
      <mechanicalReduction>1</mechanicalReduction>
    </actuator>
  </transmission>

  <transmission name="sweep">
    <type>transmission_interface/SimpleTransmission</type>
    <joint name="arm_axel_joint"/>
    <actuator name="sweep_motor">
      <hardwareInterface>EffortJointInterface</hardwareInterface>
      <mechanicalReduction>1</mechanicalReduction>
    </actuator>
  </transmission>
  
  <gazebo>
    <plugin name="gazebo_ros_control" filename="libgazebo_ros_control.so">
      <robotNamespace>/arm</robotNamespace>
    </plugin>
  </gazebo>
  
</xacro:macro>
</robot>